<?xml version="1.0"?>
<robot xmlns:xacro="http://www.ros.org/wiki/xacro">

  <xacro:macro name="rrbot" params="parent prefix *origin">

  <!-- Constants for robot dimensions -->
  <xacro:property name="PI" value="3.141592653589793238"/>
  <xacro:property name="mass" value="1" /> <!-- arbitrary value for mass -->
  <xacro:property name="r_base" value="0.1" /> <!-- Radius of base joint -->
  <xacro:property name="h_base" value="0.03" /> <!-- Vertical height of base joint -->
  <xacro:property name="d1" value="0.3" /> <!-- Vertical height of base joint -->
  <xacro:property name="r_elb" value="0.04" /> <!-- Radius of elbows -->
  <xacro:property name="t1" value="0.04" /> <!-- Link 1 offset length -->
  <xacro:property name="a1" value="0.3" /> <!-- Link 1 offset length -->
  <xacro:property name="a2" value="0.4" /> <!-- Link 2 offset length -->
  <xacro:property name="r3" value="0.01" /> <!-- Prismatic pokey bit radius -->
  <xacro:property name="d3" value="0.5" /> <!-- Prismatic pokey bit length -->
  
 <link name="world"/>
  <joint name="fixed" type="fixed">
    <parent link="world"/>
    <child link="base_link"/>
    <origin xyz="0 0 ${h_base/4}"/>
    <dynamics damping="0.7"/>
  </joint>
  
  <link name="base_link">
    <collision>
      <geometry>
        <cylinder length="${h_base}" radius="${r_base}"/>
      </geometry>
      <origin rpy="0 0 0" xyz="0 0 ${h_base/4}"/>
      <material name="white"/>
    </collision>
    
    <visual>
      <geometry>
        <cylinder length="${h_base}" radius="${r_base}"/>
      </geometry>
      <origin rpy="0 0 0" xyz="0 0 ${h_base/4}"/>
      <material name="white"/>
    </visual>
    
    <inertial>
      <origin xyz="0 0 0" rpy="0 0 0"/>
      <mass value="${mass}"/>
      <inertia
        ixx="1.0" ixy="0.0" ixz="0.0"
        iyy="1.0" iyz="0.0"
        izz="1.0"/>
    </inertial>
    
  </link>
  
  <link name="link1">
    <collision>
      <geometry>
        <cylinder length="${d1}" radius="${r_elb}"/>
      </geometry>
      <origin rpy="0 0 0" xyz="0 0 ${h_base/2 + d1/2}"/>
      <material name="white"/>
    </collision>
    <collision>
      <geometry>
        <box size="${a1} ${r_elb*2} ${t1}"/>
      </geometry>
      <origin rpy="0 0 0" xyz="${a1/2} 0 ${h_base/2 + d1 - t1/2}"/>
      <material name="orange"/>
    </collision>
    <collision>
      <geometry>
        <cylinder length="${t1}" radius="${r_elb}"/>
      </geometry>
      <origin rpy="0 0 0" xyz="${a1} 0 ${h_base/2 + d1 - t1/2}"/>
      <material name="yellow"/>
    </collision>  
  
    <visual>
      <geometry>
        <cylinder length="${d1}" radius="${r_elb}"/>
      </geometry>
      <origin rpy="0 0 0" xyz="0 0 ${h_base/2 + d1/2}"/>
      <material name="red"/>
    </visual>
    <visual>
      <geometry>
        <box size="${a1} ${r_elb*2} ${t1}"/>
      </geometry>
      <origin rpy="0 0 0" xyz="${a1/2} 0 ${h_base/2 + d1 - t1/2}"/>
      <material name="yellow"/>
    </visual>
    <visual>
      <geometry>
        <cylinder length="${t1}" radius="${r_elb}"/>
      </geometry>
      <origin rpy="0 0 0" xyz="${a1} 0 ${h_base/2 + d1 - t1/2}"/>
      <material name="orange"/>
    </visual>
    
    <inertial>
      <origin xyz="0 0 0" rpy="0 0 0"/>
      <mass value="${mass}"/>
      <inertia
        ixx="1.0" ixy="0.0" ixz="0.0"
        iyy="1.0" iyz="0.0"
        izz="1.0"/>
    </inertial>
    
  </link>
  
  <joint name="${prefix}joint1" type="revolute">
    <axis xyz="0 0 1"/>
    <limit effort="1000.0" lower="${-PI}" upper="${PI}" velocity="0.5"/>
    <origin xyz="0 0 ${h_base/2}"/>
    <parent link="base_link"/>
    <child link="link1"/>
    <dynamics damping="0.7"/>
  </joint>
  
  <link name="link2">
    <collision>
      <geometry>
        <cylinder length="${t1}" radius="${r_elb}"/>
      </geometry>
      <origin rpy="0 0 0" xyz="0 0 0"/>
      <material name="blue"/>
    </collision>
    <collision>
      <geometry>
        <box size="${a2} ${r_elb*2} ${t1}"/>
      </geometry>
      <origin rpy="0 0 0" xyz="${a2/2} 0 0"/>
      <material name="blue"/>
    </collision>
    <collision>
      <geometry>
        <cylinder length="${t1}" radius="${r_elb}"/>
      </geometry>
      <origin rpy="0 0 0" xyz="${a2} 0 0"/>
      <material name="blue"/>
    </collision>
    
    <visual>
      <geometry>
        <cylinder length="${t1}" radius="${r_elb}"/>
      </geometry>
      <origin rpy="0 0 0" xyz="0 0 0"/>
      <material name="blue"/>
    </visual>
    <visual>
      <geometry>
        <box size="${a2} ${r_elb*2} ${t1}"/>
      </geometry>
      <origin rpy="0 0 0" xyz="${a2/2} 0 0"/>
      <material name="blue"/>
    </visual>
    <visual>
      <geometry>
        <cylinder length="${t1}" radius="${r_elb}"/>
      </geometry>
      <origin rpy="0 0 0" xyz="${a2} 0 0"/>
      <material name="blue"/>
    </visual>
        
    <inertial>
      <origin xyz="0 0 0" rpy="0 0 0"/>
      <mass value="${mass}"/>
      <inertia
        ixx="1.0" ixy="0.0" ixz="0.0"
        iyy="1.0" iyz="0.0"
        izz="1.0"/>
    </inertial>    
  </link>
  
  <joint name="${prefix}joint2" type="revolute">
    <axis xyz="0 0 1"/>
    <limit effort="1000.0" lower="${-PI}" upper="${PI}" velocity="0.5"/>
    <origin xyz="${a1} 0 ${h_base/2 + d1 + t1/2}"/>
    <parent link="link1"/>
    <child link="link2"/>
    <dynamics damping="0.7"/>
  </joint>

  <link name="tool_link">
    <collision>
      <geometry>
        <cylinder length="${t1 + d1 + h_base}" radius="${r3}"/>
      </geometry>
      <origin rpy="0 0 0" xyz="0 0 0"/>
      <material name="green"/>
    </collision>
  
    <visual>
      <geometry>
        <cylinder length="${t1 + d1 + h_base}" radius="${r3}"/>
      </geometry>
      <origin rpy="0 0 0" xyz="0 0 0"/>
      <material name="green"/>
    </visual>
    
    <inertial>
      <origin xyz="0 0 0" rpy="0 0 0"/>
      <mass value="${mass}"/>
      <inertia
        ixx="1.0" ixy="0.0" ixz="0.0"
        iyy="1.0" iyz="0.0"
        izz="1.0"/>
    </inertial>
    
  </link>

  <joint name="${prefix}joint3" type="prismatic">
    <axis xyz="0 0 1"/>
    <limit effort="1000.0" lower="${-(d1 + h_base)/2}" upper="${(d1 + h_base)/2}" velocity="0.5"/>
    <origin xyz="${a2} 0 0"/>
    <parent link="link2"/>
    <child link="tool_link"/>
    <dynamics damping="0.7"/>
  </joint>



  </xacro:macro>

</robot>
